Workbook

Sheet 근로계약서
A2: 근 로 계 약 서
B5: ㈜성원애드피아 (이하 '갑'이라 한다)는 근로자 | H5: =S3 -> 0 | J5: (이하 '을'이라 한다) 과(와) 아래와 같은 내용으로 근로계약을
B6: 체결한다.
G8: ■ 아 래 ■
B9: 제 1 조 ( 근로계약기간 )
C10: ① | D10: '을'의 근로계약기간은 | G10: =TODAY() -> 46247 | I10: ~ | J10: 기한의 정함이 없는 근로계약을 체결한 것으로 한다.
D11: 계약직의 경우 별도의 계약 갱신이 이루어지지 않는 한 상기 근로계약기간의 만료로 근로관계가 자동 종료된다.
C12: ② | D12: '을'의 임금계약기간은 | G12: =+G10 -> 46247 | I12: ~ | J12: 46811 | L12: 로 한다
D13: * 새로운 임금계약이 체결되기전까지 자동 갱신된다
B15: 제 2 조 ( 근무장소 및 직종 )
C16: ① | D16: '을'의 근무장소 및 직종은 | G16: 성수사옥 | I16: / | J16: 인사팀 | L16: (으)로 한다.
C17: ② | D17: '갑'은 업무상 필요에 따라 '을'의 근무장소 및 직종을 변경할 수 있으며, '을'은 정당한 이유없이 이를 거부할 수 없다.
B19: 제 3 조 ( 근로시간 )
C20: ① | D20: 근로시간은 일 8시간, 주40시간을 원칙으로 한다.
C21: ② | D21: '을'의 기본 근로시간 및 휴게시간은 다음과 같으며, 시차출퇴근제 적용자는 회사가 지정하는 범위에서 근로자가 시업시각과
D22: 종업시각을 선택할 수 있다. 이 경우에도 휴게시간은 원칙적으로 12~13시로 한다
C24: 교대조 | E24: 시업시각 | H24: 종업시각 | K24: 휴게시간
C25: 주간조 | E25: 0.375 | H25: 0.75 | K25: 12:00~13:00
C26: 야간조
C28: ③ | D28: 갑'은 업무상 스케줄 필요에 따라 근무시간을 조정(시업 및 종업시간, 휴게시간, 단축 및 연장)할 수 있으며, 을은 주 12시간 한도내에서
D29: 시간외 근로를 요구할 수 있다.
L30: 내용 확인 및 동의 (서명)
C31: ④ | D31: 시간외 근로는 회사의 지시와 승인을 받은 시간만을 인정하며, 임의적인 시간외근로는 근로시간으로 인정하지 아니한다.
C32: ⑤ | D32: 승인없이 소정근무일에 휴무를 하는 경우 사유불문하고 무단 결근으로 처리되며, 무단결근 3회누적시 징계처리 될수 있다.
L33: 내용 확인 및 동의 (서명)
B35: 제 4 조 ( 급여 )
C36: ① | D36: '을'의 총연봉액은 | F36: =T3 -> 0 | J36: 원 이며, 이를 매월 지급한다.
C37: ② | D37: 근로자의 총연봉액은 | F37: 30000000 | J37: 원이며,
C38: ③ | D38: 근로자의 총월봉액은 | F38: =+F37/12 -> 2500000 | J38: 원이며, 월급여의 구성은 다음과 같다.
C40: 항목 | E40: 기본급 | H40: 연장근로수당 | K40: 기타수당 | N40: 월임금합계
C41: 금액 | E41: =V3 -> 0 | H41: =X3 -> 0 | K41: 0 | L41: 9496.6537 | M41: 9496.6537 | N41: =E41+H41+K41 -> 0
C42: 산정식 | E42: 시급*209 | H42: 시급*29(h)*1.5
C46: ③ | D46: 급여는 매월 1일부터 말일까지를 산정기간으로 하여, 익월 10일(휴일인 경우 익일)에 '을' 본인명의의 계좌로 지급한다.
C47: ④ | D47: 월 급여 지급시 근로소득세 및 건강보험료, 국민연금, 고용보험 등의 제세공과금을 원천징수한후 지급한다.
C48: ⑤ | D48: 결근일 및 지각, 조퇴, 임의외출 등으로 근무하지 않은 시간에 대해서는 무급을 원칙으로 하며, 해당 시간 및 일에 대한 임금을
D49: 공제할 수 있다.
C50: ⑥ | D50: 중도입사, 퇴사, 휴직, 복직 등으로 월급여 산정기간을 만근하지 못할 경우 전체 산정대상 기간 일수에 대한 근무일수를 일할계산하여
D51: 급여를 지급한다.
B53: 제 5 조 ( 퇴직금 )
C54: ① | D54: '을'의 계속근로연수가 1년 이상인 경우 '을'의 퇴직시에 계속근로연수 1년에 대하여 30일분의 평균임금을 퇴직금으로 지급한다.
...

Sheet 수습계약서
A1: 수 습(계 약) 계 약 서
B4: ㈜성원애드피아 (이하 '사업체'이라 한다)는 근로자 | H4: =S2 -> 0 | J4: (이하 근로자이라 한다) 과(와) 아래와 같은 내용으로 근로계약을
B5: 체결한다.
G7: ■ 아 래 ■
B8: 제 1 조 ( 근로계약기간 )
C9: ① | D9: 근로자의 근로계약기간은 | G9: =TODAY() -> 46247 | I9: ~ | J9: =EDATE(G9,3)-1 -> 46338 | L9: 로 하며, 계약직의 경우 별도의 계약 갱신이
D10: 이루어지지 않는 한 상기 근로계약기간의 만료로 근로관계가 자동 종료된다.
C11: ② | D11: 근로자의 임금계약기간은 | G11: =+G9 -> 46247 | I11: ~ | J11: =+J9 -> 46338 | L11: 로 한다
B14: 제 2 조 ( 근무장소 및 직종 )
C15: ① | D15: 근로자의 근무장소 및 직종은 | G15: 성수사옥 | I15: / | J15: 인사팀 | L15: (으)로 한다.
C16: ② | D16: 사업체'은 업무상 필요에 따라 근로자의 근무장소 및 직종을 변경할 수 있으며, 근로자는 정당한 이유없이 이를 거부할 수 없다.
B18: 제 3 조 ( 근로시간 )
C19: ① | D19: 근로시간은 일 8시간, 주40시간을 원칙으로 한다.
C20: ② | D20: 근로자의 기본 근로시간 및 휴게시간은 다음과 같으며, 시차출퇴근제 적용자는 회사가 지정하는 범위에서 근로자가 시업시각과
D21: 종업시각을 선택할 수 있다. 이 경우에도 휴게시간은 원칙적으로 12~13시로 한다
C23: 교대조 | E23: 시업시각 | H23: 종업시각 | K23: 휴게시간
C24: 주간조 | E24: 0.375 | H24: 0.75 | K24: 12:00~13:00
C25: 야간조
C27: ③ | D27: 사업체'은 업무상 스케줄 필요에 따라 근무시간을 조정(시업 및 종업시간, 휴게시간, 단축 및 연장)할 수 있으며, 을은 주 12시간 한도내에서
D28: 시간외 근로를 요구할 수 있다.
L29: 내용 확인 및 동의 (서명)
C30: ④ | D30: 시간외 근로는 회사의 지시와 승인을 받은 시간만을 인정하며, 임의적인 시간외근로는 근로시간으로 인정하지 아니한다.
C31: ⑤ | D31: 승인없이 소정근무일에 휴무를 하는 경우 사유불문하고 무단 결근으로 처리되며, 무단결근 3회누적시 징계처리 될수 있다.
L32: 내용 확인 및 동의 (서명)
B34: 제 4 조 ( 급여 )
C35: ① | D35: 근로자의 임금계약기간은 | G35: =G11 -> 46247 | I35: ~ | J35: =EDATE(G35,3)-1 -> 46338 | L35: 로 한다.
C36: ② | D36: 근로자의 총연봉액은 | F36: 30000000 | J36: 원이며,
C37: ③ | D37: 근로자의 총월봉액은 | F37: =+F36/12 -> 2500000 | J37: 원이며, 월급여의 구성은 다음과 같다.
C39: 항목 | E39: 기본급 | H39: 연장근로수당 | K39: 기타수당 | N39: 월임금합계
C40: 금액 | E40: =V2 -> 0 | H40: =X2 -> 0 | K40: 0 | L40: 9496.6537 | M40: 9496.6537 | N40: =E40+H40+K40 -> 0
C41: 산정식 | E41: 시급*209 | H41: 시급*29(h)*1.5
C45: ③ | D45: 급여는 매월 1일부터 말일까지를 산정기간으로 하여, 익월 10일(휴일인 경우 익일)에 근로자 본인명의의 계좌로 지급한다.
C46: ④ | D46: 월 급여 지급시 근로소득세 및 건강보험료, 국민연금, 고용보험 등의 제세공과금을 원천징수한후 지급한다.
C47: ⑤ | D47: 결근일 및 지각, 조퇴, 임의외출 등으로 근무하지 않은 시간에 대해서는 무급을 원칙으로 하며, 해당 시간 및 일에 대한 임금을
D48: 공제할 수 있다.
C49: ⑥ | D49: 중도입사, 퇴사, 휴직, 복직 등으로 월급여 산정기간을 만근하지 못할 경우 전체 산정대상 기간 일수에 대한 근무일수를 일할계산하여
D50: 급여를 지급한다.
B52: 제 5 조 ( 퇴직금 )
C53: ① | D53: 근로자의 계속근로연수가 1년 이상인 경우 근로자의 퇴직시에 계속근로연수 1년에 대하여 30일분의 평균임금을 퇴직금으로 지급한다.
C54: ② | D54: 전항의 퇴직급여와 관련하여 근로자 퇴직급여보장법 상의 요건에 따라 퇴직연금제를 도입하여 운영할 수 있다.
...

Sheet 촉탁직계약서
A2: 촉 탁 직 근 로 계 약 서
B5: 촉탁직 임용 절차에 의하여 ㈜성원애드피아 (이하 '갑'이라 한다)는 촉탁직 근로자 | K5: =S3 -> 0 | M5: (이하 '을'이라 한다) 과(와) 아래와 같은
B6: 내용으로 근로계약을 체결한다.
G8: ■ 아 래 ■
B9: 제 1 조 ( 근로계약기간 )
C10: ① | D10: '을'의 근로계약기간은 | G10: 46204 | I10: ~ | L10: 로 하며, 별도의 계약 갱신이
D11: 이루어지지 않는 한 상기 근로계약기간의 만료로 근로관계가 자동 종료된다.
C12: ② | D12: '을'의 임금계약기간은 | G12: =+G10 -> 46204 | I12: ~ | J12: =+G10+365-1 -> 46568 | L12: 로 한다
D13: * 새로운 임금계약이 체결되기전까지 자동 갱신된다
B15: 제 2 조 ( 근무장소 및 직종 )
C16: ① | D16: '을'의 근무장소 및 직종은 | G16: 성수사옥 | I16: / | J16: 인사팀 | L16: (으)로 한다.
C17: ② | D17: '갑'은 업무상 필요에 따라 '을'의 근무장소 및 직종을 변경할 수 있으며, '을'은 정당한 이유없이 이를 거부할 수 없다.
B19: 제 3 조 ( 근로일 및 근로시간 )
C20: ① | D20: 소정근로일은 월~금요일이며, 근로시간은 일 8시간, 주40시간을 원칙으로 한다.
C21: ② | D21: '을'의 기본 근로시간 및 휴게시간은 다음과 같으며, 시차출퇴근제 적용자는 회사가 지정하는 범위에서 근로자가 시업시각과
D22: 종업시각을 선택할 수 있다. 이 경우에도 휴게시간은 원칙적으로 12~13시로 한다
D24: 시업시각 | G24: 종업시각 | J24: 휴게시간
D25: 0.375 | G25: 0.75 | J25: 12:00~13:00
C27: ③ | D27: 갑'은 업무상 스케줄 필요에 따라 근무시간을 조정(시업 및 종업시간, 휴게시간, 단축 및 연장)할 수 있으며, 을은 주 12시간 한도내에서
D28: 시간외 근로를 요구할 수 있다.
L29: 내용 확인 및 동의 (서명)
C30: ④ | D30: 시간외 근로는 회사의 지시와 승인을 받은 시간만을 인정하며, 임의적인 시간외근로는 근로시간으로 인정하지 아니한다.
C31: ⑤ | D31: 승인없이 소정근무일에 휴무를 하는 경우 사유불문하고 무단 결근으로 처리되며, 무단결근 3회누적시 징계처리 될수 있다.
L32: 내용 확인 및 동의 (서명)
B34: 제 4 조 ( 급여 )
C35: ① | D35: '을'의 임금계약기간은 | G35: =G12 -> 46204 | I35: ~ | J35: =J12 -> 46568 | L35: 로 한다.
C36: ② | D36: 근로자의 총연봉액은 | F36: 30000000 | J36: 원이며,
C37: ③ | D37: 근로자의 총월봉액은 | F37: =+F36/12 -> 2500000 | J37: 원이며, 월급여의 구성은 다음과 같다.
C39: 항목 | E39: 기본급 | H39: 연장근로수당 | K39: 기타수당 | N39: 월임금합계
C40: 금액 | E40: =V3 -> 0 | H40: =X3 -> 0 | K40: 0 | L40: 9496.6537 | M40: 9496.6537 | N40: =E40+H40+K40 -> 0
C41: 산정식 | E41: 시급*209 | H41: 시급*29(h)*1.5
C44: ③ | D44: 급여는 매월 1일부터 말일까지를 산정기간으로 하여, 익월 10일(휴일인 경우 익일)에 '을' 본인명의의 계좌로 지급한다.
C45: ④ | D45: 월 급여 지급시 근로소득세 및 건강보험료, 국민연금, 고용보험 등의 제세공과금을 원천징수한후 지급한다.
C46: ⑤ | D46: 결근일 및 지각, 조퇴, 임의외출 등으로 근무하지 않은 시간에 대해서는 무급을 원칙으로 하며, 해당 시간 및 일에 대한 임금을
D47: 공제할 수 있다.
C48: ⑥ | D48: 중도입사, 퇴사, 휴직, 복직 등으로 월급여 산정기간을 만근하지 못할 경우 전체 산정대상 기간 일수에 대한 근무일수를 일할계산하여
D49: 급여를 지급한다.
B51: 제 5 조 ( 퇴직연금 )
C52: ① | D52: ① '갑’은 [근로자퇴직급여 보장법]에 따른 확정기여형 퇴직연금제도를 도입하여 운영한다. '
C53: ② | D53: ‘을’의 계속근로연수가 1년 이상인 경우, ‘갑’은 연간 임금총액의 12분의 1 이상의 확정기여형 퇴직연금 부담금을 ‘을’의 계좌에 납입한다.
...

Sheet 연봉계약서
A1: 연 봉 계 약 서 | J1: 회사명 | K1: 대표자 | L1: 회사주소 | M1: 성명 | N1: 주소 | O1: 시작일 | P1: 종료일 | Q1: 연봉
A2: ="일련번호 : "&[1]출력설정!B7 -> 일련번호 : 80 | J2: =[1]출력설정!B4 -> (주)성원애드피아 | K2: =[1]출력설정!B5 -> 정대원 | L2: =[1]출력설정!B6 -> 서울 성동구 성수일로 80 | N2: =IFERROR(INDEX([1]직원명부!$F$2:$F$97,MATCH([1]출력설정!$B$7,[1]직원명부!$B$2:$B$97,0)),"") | O2: =IFERROR(INDEX([1]직원명부!$G$2:$G$97,MATCH([1]출력설정!$B$7,[1]직원명부!$B$2:$B$97,0)),"") -> 46082 | P2: =IFERROR(INDEX([1]직원명부!$H$2:$H$97,MATCH([1]출력설정!$B$7,[1]직원명부!$B$2:$B$97,0)),"") -> 46446 | Q2: =IFERROR(INDEX([1]직원명부!$I$2:$I$97,MATCH([1]출력설정!$B$7,[1]직원명부!$B$2:$B$97,0)),"") -> 58000000
A3: (주)성원애드피아 (이하 “갑”이라고 한다)와 근로자 (이하 “을”이라 한다)은(는) 다음과 같이 연봉계약을 체결하고, 2부를 작성하여 각각 1부씩 보관한다.
A5: 제1조 (연봉계약기간)
A6: ="연봉계약기간은 "& TEXT(O2,"yyyy년 m월 d일") & "부터 " & TEXT(P2,"yyyy년 m월 d일") & "까지로 한다. 연봉기간 만료 후 새로운 연봉계약이 체결되지 않은 경우에는 직전 연봉액 기준을 준용한다." -> 연봉계약기간은 2026년 3월 1일부터 2027년 2월 28일까지로 한다. 연봉기간 만료 후 새로운 연봉계약이 체결되지 않은 경우에는 직전 연봉액 기준을 준용한다.
A8: 제2조 (연봉액 및 월급여의 구성항목)
A9: ="① “을”의 임금형태는 연봉제로 하며, 연봉액은 "&TEXT(Q2,"#,##0")&"원으로 한다." -> ① “을”의 임금형태는 연봉제로 하며, 연봉액은 58,000,000원으로 한다.
A10: ="② “을”의 월급여액은 "&TEXT(IFERROR(INDEX([1]직원명부!$J$2:$J$97,MATCH([1]출력설정!$B$7,[1]직원명부!$B$2:$B$97,0)),0),"#,##0")&"원으로 하며, 월급여의 구성항목은 다음과 같다." -> ② “을”의 월급여액은 4,833,333원으로 하며, 월급여의 구성항목은 다음과 같다.
A11: 항목 | B11: 기본급 | C11: 연장근로수당 | D11: 야간근로수당 | E11: 휴일근로수당 | F11: 월임금합계
A12: ="금액" -> 금액 | B12: =IFERROR(INDEX([1]직원명부!$K$2:$K$97,MATCH([1]출력설정!$B$7,[1]직원명부!$B$2:$B$97,0)),0) -> 4000660.1 | C12: =IFERROR(INDEX([1]직원명부!$L$2:$L$97,MATCH([1]출력설정!$B$7,[1]직원명부!$B$2:$B$97,0)),0) -> 832673.27 | D12: =IFERROR(INDEX([1]직원명부!$N$2:$N$97,MATCH([1]출력설정!$B$7,[1]직원명부!$B$2:$B$97,0)),0) -> 0 | E12: =IFERROR(INDEX([1]직원명부!$P$2:$P$97,MATCH([1]출력설정!$B$7,[1]직원명부!$B$2:$B$97,0)),0) -> 0 | F12: =SUM(B12:E12) -> 4833333.3
A13: ="산정식" -> 산정식 | B13: ="월 209시간" -> 월 209시간 | C13: ="월 "&IFERROR(INDEX([1]직원명부!$M$2:$M$97,MATCH([1]출력설정!$B$7,[1]직원명부!$B$2:$B$97,0)),0)&"시간 × 통상시급 × 150%" -> 월 29시간 × 통상시급 × 150% | D13: ="월 "&IFERROR(INDEX([1]직원명부!$O$2:$O$97,MATCH([1]출력설정!$B$7,[1]직원명부!$B$2:$B$97,0)),0)&"시간 × 통상시급 × 50%" -> 월 시간 × 통상시급 × 50% | E13: ="월 "&IFERROR(INDEX([1]직원명부!$Q$2:$Q$97,MATCH([1]출력설정!$B$7,[1]직원명부!$B$2:$B$97,0)),0)&"시간 × 통상시급 × 150%" -> 월 시간 × 통상시급 × 150%
A14: ③ 연장·야간·휴일근로는 “갑”이 지시하거나 승인한 경우에만 인정되며, 상기 임금구성항목에 포함되어 있는 법정수당을 합산한 금액을 초과한 경우는 보상휴가를 부여한다.
A15: ④ 상기 구성항목 외의 임금은 임금관리규정에 따른다.
A16: ⑤ “을”이 결근일 및 지각, 조퇴, 임의외출 등으로 근무하지 않은 시간에 대해서는 무급을 원칙으로 하며, 해당 시간 및 일에 대한 임금을 공제할 수 있다.
A17: ⑥ 중도입사, 퇴사, 휴직, 복직 등으로 월급여 산정기간을 만근하지 못할 경우 전체 산정대상 기간 일수에 대한 근무일수를 일할계산하여 급여를 지급한다.
A18: 제3조 (급여의 계산방법 및 지급방법)
A19: ① 월급여액의 산정기간은 매월 1일부터 말일까지로 한다.
A20: ② 급여의 지급 시기는 익월 10일(휴일인 경우 익일)로 하며, “을”이 지정하는 본인명의 계좌로 입금한다.
A21: ③ 월 급여 지급 시 근로소득세 및 건강보험료, 국민연금, 고용보험 등의 제세공과금을 원천징수한 후 지급한다.
A22: 제4조 (기타)
A23: ① “을”은 본인의 급여내역을 다른 직원 또는 제3자에게 누설하여서는 아니 된다.
A24: ② 이 계약에 정함이 없는 사항은 취업규칙, 급여규정 등 제규정과 노동관계법령에 따른다.
A25: =TEXT(TODAY(),"yyyy년 m월 d일") -> 2026년 8월 13일
A26: ="(갑) "&J2&CHAR(10)&"대표자 : "&K2&" (서명 또는 인)"&CHAR(10)&"주소 : "&L2 -> (갑) (주)성원애드피아 대표자 : 정대원 (서명 또는 인) 주소 : 서울 성동구 성수일로 80 | E26: ="(을)"&CHAR(10)&"성명 : "&M2&" (서명 또는 인)"&CHAR(10)&"주소 : "&N2 -> (을) 성명 : (서명 또는 인) 주소 :
A29: “을” 본인은 상기 내용을 충분히 이해하고 본 연봉계약을 체결하였으며, “갑”으로부터 연봉계약서 1부를 교부받았음을 확인합니다. 확인자 : (인)
A40: ※ 임금 구성항목 중 해당하지 않는 항목은 삭제 가능합니다.

Sheet 시급제계약서
B2: 기 간 제 근 로 계 약 서
C5: ㈜성원푸드몰 (이하 '갑'이라 한다)는 근로자 | K5: (이하 '을'이라 한다) 과(와) 아래와 같은 내용으로 근로계약을
C6: 체결한다.
H8: ■ 아 래 ■
C9: 제 1 조 ( 근로계약기간 )
D10: ① | E10: '을'의 근로계약기간은 | H10: 45413 | J10: ~ | K10: 45443 | M10: 로 하며, 별도의 계약 갱신이
E11: 이루어지지 않는 한 상기 근로계약기간의 만료로 근로관계가 자동 종료된다.
D12: ② | E12: '을'의 임금계약기간은 | H12: =H10 -> 45413 | J12: ~ | K12: =K10 -> 45443 | M12: 로 한다
E13: * 새로운 임금계약이 체결되기전까지 자동 갱신된다
C15: 제 2 조 ( 근무장소 및 직종 )
D16: ① | E16: '을'의 근무장소 및 직종은 | J16: / | M16: (으)로 한다.
D17: ② | E17: '갑'은 업무상 필요에 따라 '을'의 근무장소 및 직종을 변경할 수 있으며, '을'은 정당한 이유없이 이를 거부할 수 없다.
C19: 제 3 조 ( 근로일 및 근로시간 )
D20: ① | E20: 근로시간은 일 시간, 주 시간을 원칙으로 하며 스케줄 근무에 따른 휴일 및 근로일이 달라질 수 있다.
D21: ② | E21: '을'의 기본 근로시간 및 휴게시간은 다음과 같다.
E23: 시업시각 | H23: 종업시각 | K23: 휴게시간
D26: ③ | E26: '갑'은 업무상 스케줄 필요에 따라 근무시간을 조정(시업 및 종업시각 조정, 휴게시간 단축/연장)할 수 있으며, 을은 주 12시간 한도내에서
E27: 시간외 근로를 요구할 수 있다.
M28: 내용 확인 및 동의 (서명)
D29: ④ | E29: 시간외 근로는 회사의 지시와 승인을 받은 시간만을 인정하며, 임의적인 시간외근로는 근로시간으로 인정하지 아니한다.
D30: ⑤ | E30: 승인없이 소정근무일에 휴무를 하는 경우 사유불문하고 무단 결근으로 처리되며, 무단결근 3회누적시 징계처리 될수 있다.
M31: 내용 확인 및 동의 (서명)
C33: 제 4 조 ( 급여 )
D34: ① | E34: 시간 (일, 월) 급 : 원, 주휴수당 : 원
D35: ② | E35: 상여금 : 있음 ( ) , 없음 ( )
D36: ③ | E36: 기타급여 (제수당 등) : 있음 원 (내역별 기재 ), 없음 ( )
D37: ④ | E37: 초과근로에 대한 가산임금률: 50 %
D38: ⑤ | E38: 급여는 매월 1일부터 말일까지를 산정기간으로 하여, 익월 10일(휴일인 경우 익일)에 '을' 본인명의의 계좌로 지급한다.
D39: ⑥ | E39: 월 급여 지급시 근로소득세 및 건강보험료, 국민연금, 고용보험 등의 제세공과금을 원천징수한후 지급한다.
D40: ⑦ | E40: 결근일 및 지각, 조퇴, 임의외출 등으로 근무하지 않은 시간에 대해서는 무급을 원칙으로 하며, 해당 시간 및 일에 대한 임금을
E41: 공제할 수 있다.
D42: ⑧ | E42: 중도입사, 퇴사, 휴직, 복직 등으로 월급여 산정기간을 만근하지 못할 경우 전체 산정대상 기간 일수에 대한 근무일수를 일할계산하여
E43: 급여를 지급한다.
C45: 제 5 조 ( 퇴직급여 등 )
D46: ① | E46: ‘을’의 계속근로연수가 1년 이상인 경우, ‘갑’은 연간 임금총액의 12분의 1 이상의 확정기여형 퇴직연금 부담금을 ‘을’의 계좌에 납입한다.
D47: ② | E47: '갑'은 근로관계에서 발생한 일체의 금품을 '을'의 퇴직후 14일 이내에 지급하도록 한다.
C49: 제 6 조 ( 휴일 )
D50: ① | E50: 근로자의 날 및 주휴일(일요일)을 유급휴일로 하며, 주휴일은 1주간 소정의 근로일을 개근한 경우 부여한다.
D51: ② | E51: 매주 토요일은 무급휴무일로 한다.
C53: 제 7 조 ( 연차휴가 )
...
